Workbook
Name IQ_CH: 110000
Name IQ_CQ: 5000
Name IQ_CY: 10000
Name IQ_DAILY: 500000
Name IQ_FH: 100000
Name IQ_FQ: 500
Name IQ_FY: 1000
Name IQ_LTM: 2000
Name IQ_MONTH: 15000
Name IQ_NTM: 6000
Name IQ_WEEK: 50000
Name IQ_YTD: 3000

Sheet BG COMP BACI
A3: 1C | B3: 2C | C3: 3C | D3: 4C | E3: Numéro de compte | F3: Mapping | G3: LB | H3: FY22 | I3: FY23 | J3: FY24 | K3: FY25
A4: =LEFT(B4,1) -> 1 | B4: =LEFT(C4,2) -> 10 | C4: =LEFT(D4,3) -> 101 | D4: =LEFT(E4,4) -> 1013 | E4: 101300 | F4: Capital | G4: Capital souscrit, appelé, versé, non amorti | H4: -10000000 | I4: -10000000 | J4: -10000000 | K4: -10000000
A5: =LEFT(B5,1) -> 1 | B5: =LEFT(C5,2) -> 11 | C5: =LEFT(D5,3) -> 111 | D5: =LEFT(E5,4) -> 1110 | E5: 111000 | F5: Reserve légale | G5: RÉSERVE LÉGALE | H5: -567637 | I5: -754257 | J5: -754257 | K5: -754257
A6: =LEFT(B6,1) -> 1 | B6: =LEFT(C6,2) -> 11 | C6: =LEFT(D6,3) -> 118 | D6: =LEFT(E6,4) -> 1188 | E6: 118800 | F6: Reserve diverses | G6: Réserves diverses | H6: -10785102 | I6: -10785102 | J6: -10785102 | K6: -10785102
A7: =LEFT(B7,1) -> 1 | B7: =LEFT(C7,2) -> 12 | C7: =LEFT(D7,3) -> 121 | D7: =LEFT(E7,4) -> 1211 | E7: 121100 | F7: Report a nouveau | G7: REPORT À NOUVEAU CRÉDITEUR | K7: -652824
A8: =LEFT(B8,1) -> 1 | B8: =LEFT(C8,2) -> 12 | C8: =LEFT(D8,3) -> 129 | D8: =LEFT(E8,4) -> 1291 | E8: 129100 | F8: Report a nouveau | G8: Perte nette à reporter | H8: 34651142 | I8: 32971560 | J8: 32971560 | K8: 34656288
A9: =LEFT(B9,1) -> 1 | B9: =LEFT(C9,2) -> 13 | C9: =LEFT(D9,3) -> 130 | D9: =LEFT(E9,4) -> 1300 | E9: 130000 | G9: Résultat en attente d'affectation | K9: 0
A10: =LEFT(B10,1) -> 1 | B10: =LEFT(C10,2) -> 13 | C10: =LEFT(D10,3) -> 130 | D10: =LEFT(E10,4) -> 1301 | E10: 130100 | F10: RIA | G10: Résultat en instance d'affectation : Bénéfice | H10: 0 | I10: 0 | J10: 1684728 | K10: 0
A11: =LEFT(B11,1) -> 1 | B11: =LEFT(C11,2) -> 13 | C11: =LEFT(D11,3) -> 130 | D11: =LEFT(E11,4) -> 1309 | E11: 130900 | F11: RIA | G11: Résultat en instance d'affectation : Perte | H11: 0 | I11: 0 | J11: 0 | K11: 0
A12: =LEFT(B12,1) -> 1 | B12: =LEFT(C12,2) -> 16 | C12: =LEFT(D12,3) -> 162 | D12: =LEFT(E12,4) -> 1620 | E12: 162000 | F12: Emprunt | G12: Emprunts auprès des établissements de crédit | H12: 0 | I12: 0 | J12: 0
A13: =LEFT(B13,1) -> 1 | B13: =LEFT(C13,2) -> 16 | C13: =LEFT(D13,3) -> 162 | D13: =LEFT(E13,4) -> 1620 | E13: 162010 | F13: Emprunt | G13: Emprunts auprès des établissements de crédit - CMT 150M | K13: -124833207
A14: =LEFT(B14,1) -> 1 | B14: =LEFT(C14,2) -> 16 | C14: =LEFT(D14,3) -> 162 | D14: =LEFT(E14,4) -> 1621 | E14: 162100 | F14: Emprunt | G14: Emprunts auprès des établissements de crédit - CMT 30M | H14: -5344683 | I14: 0 | J14: 0 | K14: 0
A15: =LEFT(B15,1) -> 1 | B15: =LEFT(C15,2) -> 16 | C15: =LEFT(D15,3) -> 162 | D15: =LEFT(E15,4) -> 1622 | E15: 162200 | F15: Emprunt | G15: Emprunts auprès des établissements de crédit - CMT 20M | H15: -8539331 | I15: 0 | J15: 0 | K15: 0
A16: =LEFT(B16,1) -> 1 | B16: =LEFT(C16,2) -> 16 | C16: =LEFT(D16,3) -> 162 | D16: =LEFT(E16,4) -> 1623 | E16: 162300 | F16: Emprunt | G16: Emprunts auprès des établissements de crédit - CMT 30M Véhicule | I16: -24895681 | J16: 0 | K16: 0
A17: =LEFT(B17,1) -> 1 | B17: =LEFT(C17,2) -> 16 | C17: =LEFT(D17,3) -> 166 | D17: =LEFT(E17,4) -> 1662 | E17: 166200 | F17: Emprunt | G17: Emprunts auprès des établissements de crédit | K17: 0
A18: =LEFT(B18,1) -> 1 | B18: =LEFT(C18,2) -> 16 | C18: =LEFT(D18,3) -> 166 | D18: =LEFT(E18,4) -> 1662 | E18: 166200 | F18: Emprunt | G18: sur emprunts et dettes auprès des établissements de crédit | H18: -287539 | I18: 0 | J18: 0 | K18: 0
A19: =LEFT(B19,1) -> 1 | B19: =LEFT(C19,2) -> 17 | C19: =LEFT(D19,3) -> 173 | D19: =LEFT(E19,4) -> 1730 | E19: 173000 | F19: Dette sur crédit bail | G19: DETTES DE LOCATION ACQUISITION / CREDIT - BAIL MOBILIER | H19: -13011545 | I19: -7198580 | J19: -3332695 | K19: 0
A20: =LEFT(B20,1) -> 1 | B20: =LEFT(C20,2) -> 17 | C20: =LEFT(D20,3) -> 173 | D20: =LEFT(E20,4) -> 1731 | E20: 173100 | F20: Dette sur crédit bail | G20: DETTES DE LOCATION ACQUISITION / CREDIT - BAIL MOBILIER - CMT 30M véhicule | J20: -17546207 | K20: -9523249
A21: =LEFT(B21,1) -> 1 | B21: =LEFT(C21,2) -> 17 | C21: =LEFT(D21,3) -> 176 | D21: =LEFT(E21,4) -> 1763 | E21: 176300 | F21: Dette sur crédit bail | G21: sur dettes de location acquisition / crédit-bail mobilier | H21: -397709 | I21: -397709 | J21: -11983 | K21: -2498
A22: =LEFT(B22,1) -> 1 | B22: =LEFT(C22,2) -> 19 | C22: =LEFT(D22,3) -> 196 | D22: =LEFT(E22,4) -> 1961 | E22: 196100 | F22: Provisions pour risques et charges | G22: Provisions pour pensions et obligations similaires - engagement de retraite | H22: -4359763 | I22: -7493797 | J22: -10620691 | K22: -24352976
A23: =LEFT(B23,1) -> 2 | B23: =LEFT(C23,2) -> 21 | C23: =LEFT(D23,3) -> 213 | D23: =LEFT(E23,4) -> 2131 | E23: 213100 | F23: Logiciels | G23: Logiciels | K23: 1000000
A24: =LEFT(B24,1) -> 2 | B24: =LEFT(C24,2) -> 21 | C24: =LEFT(D24,3) -> 219 | D24: =LEFT(E24,4) -> 2193 | E24: 219300 | F24: Immobilisations en cours | G24: Logiciels et internet | I24: 116449580 | J24: 184137292 | K24: 245606888
A25: =LEFT(B25,1) -> 2 | B25: =LEFT(C25,2) -> 23 | C25: =LEFT(D25,3) -> 235 | D25: =LEFT(E25,4) -> 2351 | E25: 235100 | F25: Aménagements de bureau | G25: Installations générales | K25: 0
A26: =LEFT(B26,1) -> 2 | B26: =LEFT(C26,2) -> 23 | C26: =LEFT(D26,3) -> 235 | D26: =LEFT(E26,4) -> 2358 | E26: 235800 | F26: Aménagements de bureau | G26: Autres Aménagements de bureau | H26: 3101693 | I26: 3563557 | J26: 6445190 | K26: 22477778
A27: =LEFT(B27,1) -> 2 | B27: =LEFT(C27,2) -> 24 | C27: =LEFT(D27,3) -> 244 | D27: =LEFT(E27,4) -> 2441 | E27: 244100 | F27: Matériel et mobilier de bureau | G27: Matériel de bureau | K27: 0
A28: =LEFT(B28,1) -> 2 | B28: =LEFT(C28,2) -> 24 | C28: =LEFT(D28,3) -> 244 | D28: =LEFT(E28,4) -> 2442 | E28: 244200 | F28: Matériel informatique | G28: Matériel informatique | H28: 7641557 | I28: 24074835 | J28: 28896075 | K28: 34367685
A29: =LEFT(B29,1) -> 2 | B29: =LEFT(C29,2) -> 24 | C29: =LEFT(D29,3) -> 244 | D29: =LEFT(E29,4) -> 2444 | E29: 244400 | F29: Matériel et mobilier de bureau | G29: Mobilier de bureau | H29: 10808801 | I29: 11713348 | J29: 14736586 | K29: 27311138
A30: =LEFT(B30,1) -> 2 | B30: =LEFT(C30,2) -> 24 | C30: =LEFT(D30,3) -> 245 | D30: =LEFT(E30,4) -> 2456 | E30: 245600 | F30: Matériel de transport | G30: Matériel de transport de location-acquisition | H30: 15000000 | I30: 45700000 | J30: 45700000 | K30: 45700000
A31: =LEFT(B31,1) -> 2 | B31: =LEFT(C31,2) -> 27 | C31: =LEFT(D31,3) -> 275 | D31: =LEFT(E31,4) -> 2751 | E31: 275100 | F31: Dépots et cautionnements | G31: Dépôts pour loyers d’avance | K31: 3000000
A32: =LEFT(B32,1) -> 2 | B32: =LEFT(C32,2) -> 28 | C32: =LEFT(D32,3) -> 281 | D32: =LEFT(E32,4) -> 2813 | E32: 281300 | F32: Logiciels | G32: Amortissements des logiciels | K32: -269444
A33: =LEFT(B33,1) -> 2 | B33: =LEFT(C33,2) -> 28 | C33: =LEFT(D33,3) -> 283 | D33: =LEFT(E33,4) -> 2834 | E33: 283400 | F33: Ouvrages d'infrastructure | G33: Amortissements des installations techniques | H33: -1278605 | I33: -1898944 | J33: 0 | K33: 0
A34: =LEFT(B34,1) -> 2 | B34: =LEFT(C34,2) -> 28 | C34: =LEFT(D34,3) -> 283 | D34: =LEFT(E34,4) -> 2835 | E34: 283500 | F34: Ouvrages d'infrastructure | G34: Amortissements des aménagements de bureaux | J34: -3122176 | K34: -789989
A35: =LEFT(B35,1) -> 2 | B35: =LEFT(C35,2) -> 28 | C35: =LEFT(D35,3) -> 284 | D35: =LEFT(E35,4) -> 2844 | E35: 284400 | F35: Matériel et mobilier de bureau | G35: Amortissements du matériel et mobilier | H35: -7909488 | I35: -15510794 | J35: 0 | K35: 0
A36: =LEFT(B36,1) -> 2 | B36: =LEFT(C36,2) -> 28 | C36: =LEFT(D36,3) -> 284 | D36: =LEFT(E36,4) -> 2844 | E36: 284410 | F36: Matériel et mobilier de bureau | G36: Amortissements du mobilier de bureau | J36: -4628771
A37: =LEFT(B37,1) -> 2 | B37: =LEFT(C37,2) -> 28 | C37: =LEFT(D37,3) -> 284 | D37: =LEFT(E37,4) -> 2844 | E37: 284420 | F37: Matériel et mobilier de bureau | G37: mortissements du mobilier de bureau | K37: -6629725
A38: =LEFT(B38,1) -> 2 | B38: =LEFT(C38,2) -> 28 | C38: =LEFT(D38,3) -> 284 | D38: =LEFT(E38,4) -> 2844 | E38: 284420 | F38: Matériel et mobilier de bureau | G38: Amortissements du matériel informatique | J38: -22714796
A39: =LEFT(B39,1) -> 2 | B39: =LEFT(C39,2) -> 28 | C39: =LEFT(D39,3) -> 284 | D39: =LEFT(E39,4) -> 2844 | E39: 284420 | F39: Matériel informatique | G39: mortissements du matériel informatique | K39: -30012484
A40: =LEFT(B40,1) -> 2 | B40: =LEFT(C40,2) -> 28 | C40: =LEFT(D40,3) -> 284 | D40: =LEFT(E40,4) -> 2845 | E40: 284500 | F40: Matériel de transport | G40: Amortissements du matériel de transport | H40: -1623288 | I40: -7302072 | J40: -32768521 | K40: -44007109
A41: =LEFT(B41,1) -> 4 | B41: =LEFT(C41,2) -> 40 | C41: =LEFT(D41,3) -> 401 | D41: =LEFT(E41,4) -> 4011 | E41: 401100 | F41: Fournisseurs | G41: Fournisseurs | H41: -1707149 | I41: -5038100 | J41: -47075821 | K41: -40067935
A42: =LEFT(B42,1) -> 4 | B42: =LEFT(C42,2) -> 40 | C42: =LEFT(D42,3) -> 408 | D42: =LEFT(E42,4) -> 4081 | E42: 408100 | F42: Fournisseurs | G42: Fournisseurs - Factures Non Parvenues | H42: -3418443 | I42: -36218655 | J42: -959948 | K42: -5083299
...

Sheet BG COMP BABF
A1: Mapping | B1: C1 | C1: C2 | D1: C3 | E1: C4 | F1: NC | G1: LB | H1: FY23 | I1: FY24 | J1: FY 25
A2: Capital | B2: =LEFT(C2,1) -> 1 | C2: =LEFT(D2,2) -> 10 | D2: =_xlfn.NUMBERVALUE(LEFT(E2,3)) -> 101 | E2: =_xlfn.NUMBERVALUE(LEFT(F2,4)) -> 1013 | F2: 101310 | G2: Capital souscrit, appelé, versé, non amorti - DIOP Ibrahima | H2: -8500000 | I2: -8500000 | J2: -8500000
A3: Capital | B3: =LEFT(C3,1) -> 1 | C3: =LEFT(D3,2) -> 10 | D3: =_xlfn.NUMBERVALUE(LEFT(E3,3)) -> 101 | E3: =_xlfn.NUMBERVALUE(LEFT(F3,4)) -> 1013 | F3: 101320 | G3: Capital souscrit, appelé, versé, non amorti - BADO Hermann | H3: -1000000 | I3: -1000000 | J3: -1000000
A4: Capital | B4: =LEFT(C4,1) -> 1 | C4: =LEFT(D4,2) -> 10 | D4: =_xlfn.NUMBERVALUE(LEFT(E4,3)) -> 101 | E4: =_xlfn.NUMBERVALUE(LEFT(F4,4)) -> 1013 | F4: 101330 | G4: Capital souscrit, appelé, versé, non amorti - KONE Nombelegnerigue | H4: -500000 | I4: -500000 | J4: -500000
A5: Reserve légale | B5: =LEFT(C5,1) -> 1 | C5: =LEFT(D5,2) -> 11 | D5: =_xlfn.NUMBERVALUE(LEFT(E5,3)) -> 111 | E5: =_xlfn.NUMBERVALUE(LEFT(F5,4)) -> 1110 | F5: 111000 | G5: RÉSERVE LÉGALE | H5: 0 | I5: -353151 | J5: -1097948
A6: Report a nouveau | B6: =LEFT(C6,1) -> 1 | C6: =LEFT(D6,2) -> 12 | D6: =_xlfn.NUMBERVALUE(LEFT(E6,3)) -> 121 | E6: =_xlfn.NUMBERVALUE(LEFT(F6,4)) -> 1210 | F6: 121000 | G6: REPORT À NOUVEAU CRÉDITEUR | H6: -741664 | I6: -3849388 | J6: -10403598
A7: Report a nouveau | B7: =LEFT(C7,1) -> 1 | C7: =LEFT(D7,2) -> 12 | D7: =_xlfn.NUMBERVALUE(LEFT(E7,3)) -> 129 | E7: =_xlfn.NUMBERVALUE(LEFT(F7,4)) -> 1291 | F7: 129100 | G7: Perte nette à reporter | H7: 0 | I7: 0 | J7: 0
A8: RIA | B8: =LEFT(C8,1) -> 1 | C8: =LEFT(D8,2) -> 13 | D8: =_xlfn.NUMBERVALUE(LEFT(E8,3)) -> 130 | E8: =_xlfn.NUMBERVALUE(LEFT(F8,4)) -> 1301 | F8: 130100 | G8: Résultat en instance d'affectation : Bénéfice | H8: 0 | I8: 0 | J8: 0
A9: Emprunt | B9: =LEFT(C9,1) -> 1 | C9: =LEFT(D9,2) -> 16 | D9: =_xlfn.NUMBERVALUE(LEFT(E9,3)) -> 162 | E9: =_xlfn.NUMBERVALUE(LEFT(F9,4)) -> 1620 | F9: 162000 | G9: EMPRUNTS ET DETTES AUPRÈS DES ÉTABLISSEMENTS DE CRÉDIT | H9: 0 | I9: 0 | J9: 0
A10: Aménagements de bureau | B10: =LEFT(C10,1) -> 2 | C10: =LEFT(D10,2) -> 23 | D10: =_xlfn.NUMBERVALUE(LEFT(E10,3)) -> 235 | E10: =_xlfn.NUMBERVALUE(LEFT(F10,4)) -> 2351 | F10: 235100 | G10: Installations générales | H10: 4082500 | I10: 4082500 | J10: 4082500
A11: Matériel et mobilier de bureau | B11: =LEFT(C11,1) -> 2 | C11: =LEFT(D11,2) -> 24 | D11: =_xlfn.NUMBERVALUE(LEFT(E11,3)) -> 244 | E11: =_xlfn.NUMBERVALUE(LEFT(F11,4)) -> 2441 | F11: 244100 | G11: Matériel de bureau | H11: 5409052 | I11: 6241052 | J11: 3959052
A12: Matériel informatique | B12: =LEFT(C12,1) -> 2 | C12: =LEFT(D12,2) -> 24 | D12: =_xlfn.NUMBERVALUE(LEFT(E12,3)) -> 244 | E12: =_xlfn.NUMBERVALUE(LEFT(F12,4)) -> 2442 | F12: 244200 | G12: Matériel informatique | H12: 2128480 | I12: 2208480 | J12: 7542930
A13: Matériel et mobilier de bureau | B13: =LEFT(C13,1) -> 2 | C13: =LEFT(D13,2) -> 24 | D13: =_xlfn.NUMBERVALUE(LEFT(E13,3)) -> 244 | E13: =_xlfn.NUMBERVALUE(LEFT(F13,4)) -> 2444 | F13: 244400 | G13: Mobilier de bureau | H13: 3168696 | I13: 3168696 | J13: 3117543
A14: Matériel de transport | B14: =LEFT(C14,1) -> 2 | C14: =LEFT(D14,2) -> 24 | D14: =_xlfn.NUMBERVALUE(LEFT(E14,3)) -> 245 | E14: =_xlfn.NUMBERVALUE(LEFT(F14,4)) -> 2451 | F14: 245100 | G14: Matériel automobile | H14: 8296170 | I14: 6709370 | J14: 13815627
... A84: Virement de fonds | B84: =LEFT(C84,1) -> 5 | C84: =LEFT(D84,2) -> 58 | D84: =_xlfn.NUMBERVALUE(LEFT(E84,3)) -> 588 | E84: =_xlfn.NUMBERVALUE(LEFT(F84,4)) -> 5880 | F84: 588001 | G84: Transfert de liquidités | H84: 0 | I84: 0 | J84: 0
A85: Achat de marchandises | B85: =LEFT(C85,1) -> 6 | C85: =LEFT(D85,2) -> 60 | D85: =_xlfn.NUMBERVALUE(LEFT(E85,3)) -> 601 | E85: =_xlfn.NUMBERVALUE(LEFT(F85,4)) -> 6011 | F85: 601100 | G85: Achats dans la Région | H85: 6663594 | I85: 15548012 | J85: 103082451 | K85: =-H85/'Cdr BABF'!F8 -> 0.020907488 | L85: =-I85/'Cdr BABF'!G8 -> 0.091698024 | M85: =-J85/'Cdr BABF'!H8 -> 0.43493089 | N85: =(J85-H85)/H85 -> 14.469498 | O85: =((J85/H85)^(1/2))-1 -> 2.9331282
A86: Achat de marchandises | B86: =LEFT(C86,1) -> 6 | C86: =LEFT(D86,2) -> 60 | D86: =_xlfn.NUMBERVALUE(LEFT(E86,3)) -> 601 | E86: =_xlfn.NUMBERVALUE(LEFT(F86,4)) -> 6012 | F86: 601200 | G86: hors Région | H86: 272645541 | I86: 154017885 | J86: 132468945 | K86: =-H86/'Cdr BABF'!F8 -> 0.85544428 | L86: =-I86/'Cdr BABF'!G8 -> 0.90835637 | M86: =-J86/'Cdr BABF'!H8 -> 0.55891993 | N86: =(J86-H86)/H86 -> -0.51413493
A87: Achat de marchandises | B87: =LEFT(C87,1) -> 6 | C87: =LEFT(D87,2) -> 60 | D87: =_xlfn.NUMBERVALUE(LEFT(E87,3)) -> 601 | E87: =_xlfn.NUMBERVALUE(LEFT(F87,4)) -> 6015 | F87: 601500 | G87: Frais sur achats | H87: 39408924 | I87: 565777 | J87: 1457409 | K87: =-H87/'Cdr BABF'!F8 -> 0.12364823 | L87: =-I87/'Cdr BABF'!G8 -> 0.0033368017 | M87: =-J87/'Cdr BABF'!H8 -> 0.0061491766
A88: FNS - Electricité | B88: =LEFT(C88,1) -> 6 | C88: =LEFT(D88,2) -> 60 | D88: =_xlfn.NUMBERVALUE(LEFT(E88,3)) -> 605 | E88: =_xlfn.NUMBERVALUE(LEFT(F88,4)) -> 6052 | F88: 605200 | G88: Fournitures non stockables - Electricité | H88: 2489435 | I88: 1843333 | J88: 1362875
A89: FNS - Autres énergies | B89: =LEFT(C89,1) -> 6 | C89: =LEFT(D89,2) -> 60 | D89: =_xlfn.NUMBERVALUE(LEFT(E89,3)) -> 605 | E89: =_xlfn.NUMBERVALUE(LEFT(F89,4)) -> 6053 | F89: 605300 | G89: Fournitures non stockables – Autres énergies | H89: 4098500 | I89: 4121900 | J89: 4680000
A90: Achat de produits d'entretien | B90: =LEFT(C90,1) -> 6 | C90: =LEFT(D90,2) -> 60 | D90: =_xlfn.NUMBERVALUE(LEFT(E90,3)) -> 605 | E90: =_xlfn.NUMBERVALUE(LEFT(F90,4)) -> 6054 | F90: 605400 | G90: Fournitures d'entretien non stockables | H90: 411100 | I90: 360813 | J90: 302625
A91: Achat de fournitures | B91: =LEFT(C91,1) -> 6 | C91: =LEFT(D91,2) -> 60 | D91: =_xlfn.NUMBERVALUE(LEFT(E91,3)) -> 605 | E91: =_xlfn.NUMBERVALUE(LEFT(F91,4)) -> 6055 | F91: 605500 | G91: Fournitures de bureau non stockables | H91: 380225 | I91: 433784 | J91: 668049
A92: Achat de fournitures | B92: =LEFT(C92,1) -> 6 | C92: =LEFT(D92,2) -> 60 | D92: =_xlfn.NUMBERVALUE(LEFT(E92,3)) -> 605 | E92: =_xlfn.NUMBERVALUE(LEFT(F92,4)) -> 6055 | F92: 605501 | G92: Fournitures de bureau informatique | H92: 0 | I92: 0 | J92: 2957500
A93: Achat de fournitures | B93: =LEFT(C93,1) -> 6 | C93: =LEFT(D93,2) -> 60 | D93: =_xlfn.NUMBERVALUE(LEFT(E93,3)) -> 605 | E93: =_xlfn.NUMBERVALUE(LEFT(F93,4)) -> 6055 | F93: 605550 | G93: Fournitures divers | H93: 0 | I93: 0 | J93: 0
A94: Achat de petit matériel et outillage | B94: =LEFT(C94,1) -> 6 | C94: =LEFT(D94,2) -> 60 | D94: =_xlfn.NUMBERVALUE(LEFT(E94,3)) -> 605 | E94: =_xlfn.NUMBERVALUE(LEFT(F94,4)) -> 6056 | F94: 605600 | G94: Achats de petit matériel et outillage | H94: 0 | I94: 0 | J94: 419850
A95: Achat de petit matériel et outillage | B95: =LEFT(C95,1) -> 6 | C95: =LEFT(D95,2) -> 60 | D95: =_xlfn.NUMBERVALUE(LEFT(E95,3)) -> 605 | E95: =_xlfn.NUMBERVALUE(LEFT(F95,4)) -> 6056 | F95: 605601 | G95: Achats de petit matériel et outillage informatique | H95: 1052378 | I95: 1958236 | J95: 4899628
A96: Etudes et prestation de services | B96: =LEFT(C96,1) -> 6 | C96: =LEFT(D96,2) -> 60 | D96: =_xlfn.NUMBERVALUE(LEFT(E96,3)) -> 605 | E96: =_xlfn.NUMBERVALUE(LEFT(F96,4)) -> 6057 | F96: 605700 | G96: Achats d'études et prestations de services | H96: 10965385 | I96: 29125940 | J96: 54802867
A97: Etudes et prestation de services | B97: =LEFT(C97,1) -> 6 | C97: =LEFT(D97,2) -> 60 | D97: =_xlfn.NUMBERVALUE(LEFT(E97,3)) -> 605 | E97: =_xlfn.NUMBERVALUE(LEFT(F97,4)) -> 6057 | F97: 605701 | G97: Achats d'études et prestations de services - Frais généraux | H97: 5791178 | I97: 2929348 | J97: 13527061
A98: Travaux, matériel et équipement | B98: =LEFT(C98,1) -> 6 | C98: =LEFT(D98,2) -> 60 | D98: =_xlfn.NUMBERVALUE(LEFT(E98,3)) -> 605 | E98: =_xlfn.NUMBERVALUE(LEFT(F98,4)) -> 6058 | F98: 605800 | G98: Achats de travaux, matériels et équipements | H98: 16452263 | I98: 38047837 | J98: 29006
A99: Achat de marchandises | D99: =_xlfn.NUMBERVALUE(LEFT(E99,3)) -> 608 | E99: =_xlfn.NUMBERVALUE(LEFT(F99,4)) -> 6089 | F99: 608900 | G99: Rabais, Remises et Ristournes obtenus (non ventilés) | H99: 0 | I99: -575000
A100: Transport | B100: =LEFT(C100,1) -> 6 | C100: =LEFT(D100,2) -> 61 | D100: =_xlfn.NUMBERVALUE(LEFT(E100,3)) -> 613 | E100: =_xlfn.NUMBERVALUE(LEFT(F100,4)) -> 6130 | F100: 613000 | G100: TRANSPORTS POUR LE COMPTE DE TIERS | H100: 0 | I100: 0 | J100: 0
A101: Transport | B101: =LEFT(C101,1) -> 6 | C101: =LEFT(D101,2) -> 61 | D101: =_xlfn.NUMBERVALUE(LEFT(E101,3)) -> 616 | E101: =_xlfn.NUMBERVALUE(LEFT(F101,4)) -> 6160 | F101: 616000 | G101: TRANSPORTS DE PLIS | H101: 0 | I101: 0 | J101: 88000
A102: Transport | B102: =LEFT(C102,1) -> 6 | C102: =LEFT(D102,2) -> 61 | D102: =_xlfn.NUMBERVALUE(LEFT(E102,3)) -> 616 | E102: =_xlfn.NUMBERVALUE(LEFT(F102,4)) -> 6161 | F102: 616100 | G102: Frais d'expédition et Livraison de marchandises | H102: 0 | I102: 0 | J102: 1124051
A103: Transport | B103: =LEFT(C103,1) -> 6 | C103: =LEFT(D103,2) -> 61 | D103: =_xlfn.NUMBERVALUE(LEFT(E103,3)) -> 618 | E103: =_xlfn.NUMBERVALUE(LEFT(F103,4)) -> 6181 | F103: 618100 | G103: Voyages et déplacements | H103: 8320800 | I103: 5312900 | J103: 5463801
A104: Transport | B104: =LEFT(C104,1) -> 6 | C104: =LEFT(D104,2) -> 61 | D104: =_xlfn.NUMBERVALUE(LEFT(E104,3)) -> 618 | E104: =_xlfn.NUMBERVALUE(LEFT(F104,4)) -> 6183 | F104: 618300 | G104: Transports administratifs | H104: 2050000 | I104: 1045000 | J104: 252116
A105: Charges locatives matières diverses | B105: =LEFT(C105,1) -> 6 | C105: =LEFT(D105,2) -> 62 | D105: =_xlfn.NUMBERVALUE(LEFT(E105,3)) -> 622 | E105: =_xlfn.NUMBERVALUE(LEFT(F105,4)) -> 6221 | F105: 622100 | G105: Locations de terrains | H105: 1200000 | I105: 0
A106: Charges locatives matières diverses | B106: =LEFT(C106,1) -> 6 | C106: =LEFT(D106,2) -> 62 | D106: =_xlfn.NUMBERVALUE(LEFT(E106,3)) -> 622 | E106: =_xlfn.NUMBERVALUE(LEFT(F106,4)) -> 6222 | F106: 622200 | G106: Locations de bâtiments | H106: 7200000 | I106: 7200000 | J106: 8132568
A107: Charges locatives matières diverses | B107: =LEFT(C107,1) -> 6 | C107: =LEFT(D107,2) -> 62 | D107: =_xlfn.NUMBERVALUE(LEFT(E107,3)) -> 622 | E107: =_xlfn.NUMBERVALUE(LEFT(F107,4)) -> 6223 | F107: 622300 | G107: Locations de matériels et outillages | H107: 0 | I107: 0 | J107: 40500
A108: Charges locatives matières diverses | B108: =LEFT(C108,1) -> 6 | C108: =LEFT(D108,2) -> 62 | D108: =_xlfn.NUMBERVALUE(LEFT(E108,3)) -> 622 | E108: =_xlfn.NUMBERVALUE(LEFT(F108,4)) -> 6228 | F108: 622800 | G108: Locations et charges locatives diverses | H108: 2110880 | I108: 708118 | J108: 1168947
A109: Charges locatives matières diverses | B109: =LEFT(C109,1) -> 6 | C109: =LEFT(D109,2) -> 62 | D109: =_xlfn.NUMBERVALUE(LEFT(E109,3)) -> 622 | E109: =_xlfn.NUMBERVALUE(LEFT(F109,4)) -> 6228 | F109: 622801 | G109: Locations pour clients | H109: 0 | I109: 0 | J109: 195600
...

Sheet Cdr BABF
E2: Box Africa BF - P&L
C3: Mapping | E3: mFCFA | F3: FY23 | G3: FY24 | H3: FY25 | J3: CAGR 23-25 | L3: Commentaires
C4: Ventes de marchandises | E4: Travaux et Services vendus | F4: =-SUMIF('BG COMP BABF'!$A:$A,'Cdr BABF'!$C4,'BG COMP BABF'!H:H) -> 366135552 | G4: =-SUMIF('BG COMP BABF'!$A:$A,'Cdr BABF'!$C4,'BG COMP BABF'!I:I) -> 240296378 | H4: =-SUMIF('BG COMP BABF'!$A:$A,'Cdr BABF'!$C4,'BG COMP BABF'!J:J) -> 287733762 | J4: =IFERROR((H4/F4)^(1/2)-1,"n.a") -> -0.11350873 | M4: =F4/F6 -> 0.75386582 | N4: =G4/G6 -> 0.62257692 | O4: =H4/H6 -> 0.49662379 | P4: =AVERAGE(M4:O4) -> 0.62435551
C5: Services vendus | E5: Services vendus | F5: =-SUMIF('BG COMP BABF'!$A:$A,'Cdr BABF'!$C5,'BG COMP BABF'!H:H) -> 119541793 | G5: =-SUMIF('BG COMP BABF'!$A:$A,'Cdr BABF'!$C5,'BG COMP BABF'!I:I) -> 145674205 | H5: =-SUMIF('BG COMP BABF'!$A:$A,'Cdr BABF'!$C5,'BG COMP BABF'!J:J) -> 291645980 | J5: =IFERROR((H5/F5)^(1/2)-1,"n.a") -> 0.56195355 | M5: =F5/F6 -> 0.24613418 | N5: =G5/G6 -> 0.37742308 | O5: =H5/H6 -> 0.50337621 | P5: =AVERAGE(M5:O5) -> 0.37564449
E6: Chiffre d'affaires | F6: =SUM(F4:F5) -> 485677345 | G6: =SUM(G4:G5) -> 385970583 | H6: =SUM(H4:H5) -> 579379742 | J6: =IFERROR((H6/F6)^(1/2)-1,"n.a") -> 0.092213978
C7: Production immobilisée | E7: Production immobilisée | F7: =-SUMIF('BG COMP BABF'!$A:$A,'Cdr BABF'!$C7,'BG COMP BABF'!H:H) -> 0 | G7: =-SUMIF('BG COMP BABF'!A:A,'Cdr BABF'!$C7,'BG COMP BABF'!I:I) -> 0 | H7: =-SUMIF('BG COMP BABF'!$A:$A,'Cdr BABF'!$C7,'BG COMP BABF'!J:J) -> 0 | J7: =IFERROR((H7/F7)^(1/2)-1,"n.a") -> n.a
C8: Achat de marchandises | E8: Achats de marchandises | F8: =-SUMIF('BG COMP BABF'!$A:$A,'Cdr BABF'!$C8,'BG COMP BABF'!H:H) -> -318718059 | G8: =-SUMIF('BG COMP BABF'!A:A,'Cdr BABF'!$C8,'BG COMP BABF'!I:I) -> -169556674 | H8: =-SUMIF('BG COMP BABF'!$A:$A,'Cdr BABF'!$C8,'BG COMP BABF'!J:J) -> -237008805 | J8: =IFERROR((H8/F8)^(1/2)-1,"n.a") -> -0.13765926
C9: Charges de personnel | E9: Charges de personnel | F9: =-SUMIF('BG COMP BABF'!$A:$A,'Cdr BABF'!$C9,'BG COMP BABF'!H:H) -> -50023326 | G9: =-SUMIF('BG COMP BABF'!A:A,'Cdr BABF'!$C9,'BG COMP BABF'!I:I) -> -51573436 | H9: =-SUMIF('BG COMP BABF'!$A:$A,'Cdr BABF'!$C9,'BG COMP BABF'!J:J) -> -57624113 | J9: =IFERROR((H9/F9)^(1/2)-1,"n.a") -> 0.07328694
C10: Transport | E10: Transport | F10: =-SUMIF('BG COMP BABF'!$A:$A,'Cdr BABF'!$C10,'BG COMP BABF'!H:H) -> -10370800 | G10: =-SUMIF('BG COMP BABF'!A:A,'Cdr BABF'!$C10,'BG COMP BABF'!I:I) -> -6357900 | H10: =-SUMIF('BG COMP BABF'!$A:$A,'Cdr BABF'!$C10,'BG COMP BABF'!J:J) -> -6927968 | J10: =IFERROR((H10/F10)^(1/2)-1,"n.a") -> -0.18267119
C11: Sous traitance | E11: Sous traitance | F11: =-SUMIF('BG COMP BABF'!$A:$A,'Cdr BABF'!$C11,'BG COMP BABF'!H:H) -> 0 | G11: =-SUMIF('BG COMP BABF'!A:A,'Cdr BABF'!$C11,'BG COMP BABF'!I:I) -> 0 | H11: =-SUMIF('BG COMP BABF'!$A:$A,'Cdr BABF'!$C11,'BG COMP BABF'!J:J) -> 0 | J11: =IFERROR((H11/F11)^(1/2)-1,"n.a") -> n.a
C12: Charges locatives matières diverses | E12: Charges locatives matières diverses | F12: =-SUMIF('BG COMP BABF'!$A:$A,'Cdr BABF'!$C12,'BG COMP BABF'!H:H) -> -10510880 | G12: =-SUMIF('BG COMP BABF'!A:A,'Cdr BABF'!$C12,'BG COMP BABF'!I:I) -> -8108118 | H12: =-SUMIF('BG COMP BABF'!$A:$A,'Cdr BABF'!$C12,'BG COMP BABF'!J:J) -> -9537615 | J12: =IFERROR((H12/F12)^(1/2)-1,"n.a") -> -0.047422422
C13: Ent. & réparatIon | E13: Ent. & réparatIon | F13: =-SUMIF('BG COMP BABF'!$A:$A,'Cdr BABF'!$C13,'BG COMP BABF'!H:H) -> -1317617 | G13: =-SUMIF('BG COMP BABF'!A:A,'Cdr BABF'!$C13,'BG COMP BABF'!I:I) -> -2594717 | H13: =-SUMIF('BG COMP BABF'!$A:$A,'Cdr BABF'!$C13,'BG COMP BABF'!J:J) -> -2215600 | J13: =IFERROR((H13/F13)^(1/2)-1,"n.a") -> 0.29673455
C14: Assurances | E14: Assurances | F14: =-SUMIF('BG COMP BABF'!$A:$A,'Cdr BABF'!$C14,'BG COMP BABF'!H:H) -> -4173750 | G14: =-SUMIF('BG COMP BABF'!A:A,'Cdr BABF'!$C14,'BG COMP BABF'!I:I) -> -1754988 | H14: =-SUMIF('BG COMP BABF'!$A:$A,'Cdr BABF'!$C14,'BG COMP BABF'!J:J) -> -1276192 | J14: =IFERROR((H14/F14)^(1/2)-1,"n.a") -> -0.44703863
C15: Etudes, recherches et documentation | E15: Etudes, recherches et documentation | F15: =-SUMIF('BG COMP BABF'!$A:$A,'Cdr BABF'!$C15,'BG COMP BABF'!H:H) -> 0 | G15: =-SUMIF('BG COMP BABF'!A:A,'Cdr BABF'!$C15,'BG COMP BABF'!I:I) -> 0 | H15: =-SUMIF('BG COMP BABF'!$A:$A,'Cdr BABF'!$C15,'BG COMP BABF'!J:J) -> -48000 | J15: =IFERROR((H15/F15)^(1/2)-1,"n.a") -> n.a
C16: Publicité et relations publiques | E16: Publicité et relations publiques | F16: =-SUMIF('BG COMP BABF'!$A:$A,'Cdr BABF'!$C16,'BG COMP BABF'!H:H) -> 0 | G16: =-SUMIF('BG COMP BABF'!A:A,'Cdr BABF'!$C16,'BG COMP BABF'!I:I) -> -19000 | H16: =-SUMIF('BG COMP BABF'!$A:$A,'Cdr BABF'!$C16,'BG COMP BABF'!J:J) -> -52016171 | J16: =IFERROR((H16/F16)^(1/2)-1,"n.a") -> n.a
C17: Frais de télécommunication | E17: Frais de télécommunication | F17: =-SUMIF('BG COMP BABF'!$A:$A,'Cdr BABF'!$C17,'BG COMP BABF'!H:H) -> -2708865 | G17: =-SUMIF('BG COMP BABF'!A:A,'Cdr BABF'!$C17,'BG COMP BABF'!I:I) -> -2186056 | H17: =-SUMIF('BG COMP BABF'!$A:$A,'Cdr BABF'!$C17,'BG COMP BABF'!J:J) -> -3414757 | J17: =IFERROR((H17/F17)^(1/2)-1,"n.a") -> 0.12275816
C18: Frais bancaires | E18: Frais bancaires | F18: =-SUMIF('BG COMP BABF'!$A:$A,'Cdr BABF'!$C18,'BG COMP BABF'!H:H) -> -9023514 | G18: =-SUMIF('BG COMP BABF'!A:A,'Cdr BABF'!$C18,'BG COMP BABF'!I:I) -> -13831789 | H18: =-SUMIF('BG COMP BABF'!$A:$A,'Cdr BABF'!$C18,'BG COMP BABF'!J:J) -> -14474043 | J18: =IFERROR((H18/F18)^(1/2)-1,"n.a") -> 0.2665055
... C22: Travaux, matériel et équipement | E22: Travaux, matériel et équipement | F22: =-SUMIF('BG COMP BABF'!$A:$A,'Cdr BABF'!$C22,'BG COMP BABF'!H:H) -> -16452263 | G22: =-SUMIF('BG COMP BABF'!A:A,'Cdr BABF'!$C22,'BG COMP BABF'!I:I) -> -38047837 | H22: =-SUMIF('BG COMP BABF'!$A:$A,'Cdr BABF'!$C22,'BG COMP BABF'!J:J) -> -29006 | J22: =IFERROR((H22/F22)^(1/2)-1,"n.a") -> -0.95801143
E23: Services extérieurs | F23: =SUM(F11:F22) -> -76022421 | G23: =SUM(G11:G22) -> -126668255 | H23: =SUM(H11:H22) -> -193873124 | J23: =IFERROR((H23/F23)^(1/2)-1,"n.a") -> 0.59693764 | M23: =F4*(1+J4) -> 3.2457597e+08
C24: FNS - Electricité | E24: Electricité | F24: =-SUMIF('BG COMP BABF'!$A:$A,'Cdr BABF'!$C24,'BG COMP BABF'!H:H) -> -2489435 | G24: =-SUMIF('BG COMP BABF'!A:A,'Cdr BABF'!$C24,'BG COMP BABF'!I:I) -> -1843333 | H24: =-SUMIF('BG COMP BABF'!$A:$A,'Cdr BABF'!$C24,'BG COMP BABF'!J:J) -> -1362875 | J24: =IFERROR((H24/F24)^(1/2)-1,"n.a") -> -0.26009218
C25: FNS - Autres énergies | E25: Autres énergies | F25: =-SUMIF('BG COMP BABF'!$A:$A,'Cdr BABF'!$C25,'BG COMP BABF'!H:H) -> -4098500 | G25: =-SUMIF('BG COMP BABF'!A:A,'Cdr BABF'!$C25,'BG COMP BABF'!I:I) -> -4121900 | H25: =-SUMIF('BG COMP BABF'!$A:$A,'Cdr BABF'!$C25,'BG COMP BABF'!J:J) -> -4680000 | J25: =IFERROR((H25/F25)^(1/2)-1,"n.a") -> 0.068588403
C26: Achat de produits d'entretien | E26: Achat de produits d'entretien | F26: =-SUMIF('BG COMP BABF'!$A:$A,'Cdr BABF'!$C26,'BG COMP BABF'!H:H) -> -411100 | G26: =-SUMIF('BG COMP BABF'!A:A,'Cdr BABF'!$C26,'BG COMP BABF'!I:I) -> -360813 | H26: =-SUMIF('BG COMP BABF'!$A:$A,'Cdr BABF'!$C26,'BG COMP BABF'!J:J) -> -302625 | J26: =IFERROR((H26/F26)^(1/2)-1,"n.a") -> -0.14201704
C27: Achat de fournitures | E27: Achat de fournitures | F27: =-SUMIF('BG COMP BABF'!$A:$A,'Cdr BABF'!$C27,'BG COMP BABF'!H:H) -> -380225 | G27: =-SUMIF('BG COMP BABF'!A:A,'Cdr BABF'!$C27,'BG COMP BABF'!I:I) -> -433784 | H27: =-SUMIF('BG COMP BABF'!$A:$A,'Cdr BABF'!$C27,'BG COMP BABF'!J:J) -> -3625549 | J27: =IFERROR((H27/F27)^(1/2)-1,"n.a") -> 2.0879237
C28: Achat de petit matériel et outillage | E28: Achat de petit matériel et outillage | F28: =-SUMIF('BG COMP BABF'!$A:$A,'Cdr BABF'!$C28,'BG COMP BABF'!H:H) -> -1052378 | G28: =-SUMIF('BG COMP BABF'!A:A,'Cdr BABF'!$C28,'BG COMP BABF'!I:I) -> -1958236 | H28: =-SUMIF('BG COMP BABF'!$A:$A,'Cdr BABF'!$C28,'BG COMP BABF'!J:J) -> -5319478 | J28: =IFERROR((H28/F28)^(1/2)-1,"n.a") -> 1.2482708
E29: Autres achats et charges externes | F29: =SUM(F24:F28) -> -8431638 | G29: =SUM(G24:G28) -> -8718066 | H29: =SUM(H24:H28) -> -15290527 | J29: =IFERROR((H29/F29)^(1/2)-1,"n.a") -> 0.3466516
C30: Impôts et taxes | E30: Impôts et taxes | F30: =-SUMIF('BG COMP BABF'!$A:$A,'Cdr BABF'!$C30,'BG COMP BABF'!H:H) -> -3876717 | G30: =-SUMIF('BG COMP BABF'!A:A,'Cdr BABF'!$C30,'BG COMP BABF'!I:I) -> -5256287 | H30: =-SUMIF('BG COMP BABF'!$A:$A,'Cdr BABF'!$C30,'BG COMP BABF'!J:J) -> -8721750 | J30: =IFERROR((H30/F30)^(1/2)-1,"n.a") -> 0.49992577
C31: Autres produits | E31: Autres produits | F31: =-SUMIF('BG COMP BABF'!$A:$A,'Cdr BABF'!$C31,'BG COMP BABF'!H:H) -> 1687290 | G31: =-SUMIF('BG COMP BABF'!$A:$A,'Cdr BABF'!$C31,'BG COMP BABF'!I:I) -> 0 | H31: =-SUMIF('BG COMP BABF'!$A:$A,'Cdr BABF'!$C31,'BG COMP BABF'!J:J) -> 13306430 | J31: =IFERROR((H31/F31)^(1/2)-1,"n.a") -> 1.8082509
C32: Autres charges | E32: Autres charges | F32: =-SUMIF('BG COMP BABF'!$A:$A,'Cdr BABF'!$C32,'BG COMP BABF'!H:H) -> -1575953 | G32: =-SUMIF('BG COMP BABF'!A:A,'Cdr BABF'!$C32,'BG COMP BABF'!I:I) -> -99523 | H32: =-SUMIF('BG COMP BABF'!$A:$A,'Cdr BABF'!$C32,'BG COMP BABF'!J:J) -> -3465116 | J32: =IFERROR((H32/F32)^(1/2)-1,"n.a") -> 0.48281598
E33: Autres produits et charges | F33: =-SUMIF('BG COMP BABF'!$A:$A,'Cdr BABF'!$C33,'BG COMP BABF'!H:H) -> 0 | G33: =G31+G32 -> -99523 | H33: =H31+H32 -> 9841314 | J33: =IFERROR((H33/F33)^(1/2)-1,"n.a") -> n.a
E34: Charges d'exploitation | F34: =F33+F30+F29+F23+F10+F9 -> -148724902 | G34: =G33+G30+G29+G23+G10+G9 -> -198673467 | H34: =H33+H30+H29+H23+H10+H9 -> -272596168 | J34: =IFERROR((H34/F34)^(1/2)-1,"n.a") -> 0.35384214
E35: EBITDA | F35: =+SUM(F6,F8,F9,F10,F23,F29,F30,F33) -> 18234384 | G35: =+SUM(G6,G8,G9,G10,G23,G29,G30,G33) -> 17740442 | H35: =+SUM(H6,H8,H9,H10,H23,H29,H30,H33) -> 69774769 | J35: =IFERROR((H35/F35)^(1/2)-1,"n.a") -> 0.95615676 | M35: =(H35-G35)/G35 -> 2.9330908
E36: EBITDA (% CA) | F36: =IFERROR(F35/F$6,"n.a") -> 0.037544234 | G36: =IFERROR(G35/G$6,"n.a") -> 0.045963197 | H36: =IFERROR(H35/H$6,"n.a") -> 0.12043012 | J36: =AVERAGE(F36:H36) -> 0.067979182 | M36: =AVERAGE(F36:H36) -> 0.067979182
C37: Reprises de provisions | E37: Reprises de provisions | F37: =-SUMIF('BG COMP BABF'!$A:$A,'Cdr BABF'!$C37,'BG COMP BABF'!H:H) -> 0 | G37: =-SUMIF('BG COMP BABF'!A:A,'Cdr BABF'!$C37,'BG COMP BABF'!I:I) -> 0 | H37: =-SUMIF('BG COMP BABF'!$A:$A,'Cdr BABF'!$C37,'BG COMP BABF'!J:J) -> 256022 | J37: =IFERROR((H37/F37)^(1/2)-1,"n.a") -> n.a
C38: Dotations aux provisions pour risques et charges | E38: Provisions pour risques et charges | F38: =-SUMIF('BG COMP BABF'!$A:$A,'Cdr BABF'!$C38,'BG COMP BABF'!H:H) -> 0 | G38: =-SUMIF('BG COMP BABF'!A:A,'Cdr BABF'!$C38,'BG COMP BABF'!I:I) -> 0 | H38: =-SUMIF('BG COMP BABF'!$A:$A,'Cdr BABF'!$C38,'BG COMP BABF'!J:J) -> 0 | J38: =IFERROR((H38/F38)^(1/2)-1,"n.a") -> n.a
C39: Dotations aux at | E39: Dotations aux amortissements | F39: =-SUMIF('BG COMP BABF'!$A:$A,'Cdr BABF'!$C39,'BG COMP BABF'!H:H) -> -3531374 | G39: =-SUMIF('BG COMP BABF'!A:A,'Cdr BABF'!$C39,'BG COMP BABF'!I:I) -> -3834084 | H39: =-SUMIF('BG COMP BABF'!$A:$A,'Cdr BABF'!$C39,'BG COMP BABF'!J:J) -> -4925482 | J39: =IFERROR((H39/F39)^(1/2)-1,"n.a") -> 0.18100711
E40: D&A | F40: =SUM(F37:F39) -> -3531374 | G40: =SUM(G37:G39) -> -3834084 | H40: =SUM(H37:H39) -> -4669460 | J40: =IFERROR((H40/F40)^(1/2)-1,"n.a") -> 0.1499037
E41: EBIT | F41: =F35+F40 -> 14703010 | G41: =G35+G40 -> 13906358 | H41: =H35+H40 -> 65105309 | J41: =IFERROR((H41/F41)^(1/2)-1,"n.a") -> 1.1042875
E42: EBIT (% CA) | F42: =IFERROR(F41/F$6,"n.a") -> 0.030273205 | G42: =IFERROR(G41/G$6,"n.a") -> 0.03602958 | H42: =IFERROR(H41/H$6,"n.a") -> 0.1123707 | J42: =AVERAGE(F42:H42) -> 0.05955783
C43: Produits d'intérêts | E43: Produits financiers | F43: =-SUMIF('BG COMP BABF'!$A:$A,'Cdr BABF'!$C43,'BG COMP BABF'!H:H) -> 0 | G43: =-SUMIF('BG COMP BABF'!A:A,'Cdr BABF'!$C43,'BG COMP BABF'!I:I) -> 4313136 | H43: =-SUMIF('BG COMP BABF'!$A:$A,'Cdr BABF'!$C43,'BG COMP BABF'!J:J) -> -883954 | J43: =IFERROR((H43/F43)^(1/2)-1,"n.a") -> n.a
C44: Intérêts sur emprunts | E44: Intérêts sur emprunts | F44: =-SUMIF('BG COMP BABF'!$A:$A,'Cdr BABF'!$C44,'BG COMP BABF'!H:H) -> -7904467 | G44: =-SUMIF('BG COMP BABF'!A:A,'Cdr BABF'!$C44,'BG COMP BABF'!I:I) -> -7637078 | H44: =-SUMIF('BG COMP BABF'!$A:$A,'Cdr BABF'!$C44,'BG COMP BABF'!J:J) -> 0 | J44: =IFERROR((H44/F44)^(1/2)-1,"n.a") -> -1
...

Sheet Bilan BABF
D6: Projet BOX AFRICA - Actif net BABF
B7: Mapping | D7: En mFCFA | E7: FY22 | F7: FY23 | G7: FY24 | H7: FY25
B8: Ouvrages d'infrastructure | D8: Ouvrages d'infrastructure | F8: =(((-SUMIF('BG COMP BABF'!$A:$A,$B8,'BG COMP BABF'!H:H)))/1000000)*-1 -> -1.958114 | G8: =(((-SUMIF('BG COMP BABF'!$A:$A,$B8,'BG COMP BABF'!I:I)))/1000000)*-1 -> -2.774614 | H8: =(((-SUMIF('BG COMP BABF'!$A:$A,$B8,'BG COMP BABF'!J:J)))/1000000)*-1 -> -3.591114
B9: Matériel et outillage | D9: Matériel et outillage | F9: =(((-SUMIF('BG COMP BABF'!$A:$A,$B9,'BG COMP BABF'!H:H)))/1000000)*-1 -> 0 | G9: =(((-SUMIF('BG COMP BABF'!$A:$A,$B9,'BG COMP BABF'!I:I)))/1000000)*-1 -> 0 | H9: =(((-SUMIF('BG COMP BABF'!$A:$A,$B9,'BG COMP BABF'!J:J)))/1000000)*-1 -> 0
B10: Matériel de bureau | D10: Matériel de bureau | F10: =(((-SUMIF('BG COMP BABF'!$A:$A,$B10,'BG COMP BABF'!H:H)))/1000000)*-1 -> 0 | G10: =(((-SUMIF('BG COMP BABF'!$A:$A,$B10,'BG COMP BABF'!I:I)))/1000000)*-1 -> 0 | H10: =(((-SUMIF('BG COMP BABF'!$A:$A,$B10,'BG COMP BABF'!J:J)))/1000000)*-1 -> 0
B11: Aménagements de bureau | D11: Aménagements de bureau | F11: =(((-SUMIF('BG COMP BABF'!$A:$A,$B11,'BG COMP BABF'!H:H)))/1000000)*-1 -> 4.0825 | G11: =(((-SUMIF('BG COMP BABF'!$A:$A,$B11,'BG COMP BABF'!I:I)))/1000000)*-1 -> 4.0825 | H11: =(((-SUMIF('BG COMP BABF'!$A:$A,$B11,'BG COMP BABF'!J:J)))/1000000)*-1 -> 4.0825
B12: Matériel informatique | D12: Matériel informatique | F12: =(((-SUMIF('BG COMP BABF'!$A:$A,$B12,'BG COMP BABF'!H:H)))/1000000)*-1 -> 2.12848 | G12: =(((-SUMIF('BG COMP BABF'!$A:$A,$B12,'BG COMP BABF'!I:I)))/1000000)*-1 -> 2.20848 | H12: =(((-SUMIF('BG COMP BABF'!$A:$A,$B12,'BG COMP BABF'!J:J)))/1000000)*-1 -> 7.54293
B13: Matériel et mobilier de bureau | D13: Matériel et mobilier de bureau | F13: =(((-SUMIF('BG COMP BABF'!$A:$A,$B13,'BG COMP BABF'!H:H)))/1000000)*-1 -> 2.047227 | G13: =(((-SUMIF('BG COMP BABF'!$A:$A,$B13,'BG COMP BABF'!I:I)))/1000000)*-1 -> 1.552517 | H13: =(((-SUMIF('BG COMP BABF'!$A:$A,$B13,'BG COMP BABF'!J:J)))/1000000)*-1 -> -3.017904
B14: Mat. & mob. des logements du pers. | D14: Mat. & mob. des logements du pers. | F14: =(((-SUMIF('BG COMP BABF'!$A:$A,$B14,'BG COMP BABF'!H:H)))/1000000)*-1 -> 0 | G14: =(((-SUMIF('BG COMP BABF'!$A:$A,$B14,'BG COMP BABF'!I:I)))/1000000)*-1 -> 0 | H14: =(((-SUMIF('BG COMP BABF'!$A:$A,$B14,'BG COMP BABF'!J:J)))/1000000)*-1 -> 0
B15: Matériel de transport | D15: Matériel de transport | F15: =(((-SUMIF('BG COMP BABF'!$A:$A,$B15,'BG COMP BABF'!H:H)))/1000000)*-1 -> 7.865498 | G15: =(((-SUMIF('BG COMP BABF'!$A:$A,$B15,'BG COMP BABF'!I:I)))/1000000)*-1 -> 6.201743 | H15: =(((-SUMIF('BG COMP BABF'!$A:$A,$B15,'BG COMP BABF'!J:J)))/1000000)*-1 -> 9.960051
B16: Avances et acomptes | D16: Avances et acomptes | F16: =(((-SUMIF('BG COMP BABF'!$A:$A,$B16,'BG COMP BABF'!H:H)))/1000000)*-1 -> 0 | G16: =(((-SUMIF('BG COMP BABF'!$A:$A,$B16,'BG COMP BABF'!I:I)))/1000000)*-1 -> 0 | H16: =(((-SUMIF('BG COMP BABF'!$A:$A,$B16,'BG COMP BABF'!J:J)))/1000000)*-1 -> 0
D17: Immobilisations corporelles | F17: =SUM(F8:F16) -> 14.165591 | G17: =SUM(G8:G16) -> 11.270626 | H17: =SUM(H8:H16) -> 14.976463
B18: Dépots et cautionnements | D18: Dépots et cautionnements | F18: =(((-SUMIF('BG COMP BABF'!$A:$A,$B18,'BG COMP BABF'!H:H)))/1000000)*-1 -> 0 | G18: =(((-SUMIF('BG COMP BABF'!$A:$A,$B18,'BG COMP BABF'!I:I)))/1000000)*-1 -> 0 | H18: =(((-SUMIF('BG COMP BABF'!$A:$A,$B18,'BG COMP BABF'!J:J)))/1000000)*-1 -> 1.86558
D19: Immobilisations financières | F19: =SUM(F18) -> 0 | G19: =SUM(G18) -> 0 | H19: =SUM(H18) -> 1.86558
B20: Immobilisations en cours | D20: Immobilisations en cours | F20: =(((-SUMIF('BG COMP BABF'!$A:$A,$B20,'BG COMP BABF'!H:H)))/1000000)*-1 -> 123.49674 | G20: =(((-SUMIF('BG COMP BABF'!$A:$A,$B20,'BG COMP BABF'!I:I)))/1000000)*-1 -> 73.074271 | H20: =(((-SUMIF('BG COMP BABF'!$A:$A,$B20,'BG COMP BABF'!J:J)))/1000000)*-1 -> 0
D21: Actifs immobilisés | F21: =SUM(F19:F20,F17) -> 137.66233 | G21: =SUM(G19:G20,G17) -> 84.344897 | H21: =SUM(H19:H20,H17) -> 16.842043
B22: Clients | D22: Créances clients | F22: =(((-SUMIF('BG COMP BABF'!$A:$A,$B22,'BG COMP BABF'!H:H)))/1000000)*-1 -> 10.690842 | G22: =(((-SUMIF('BG COMP BABF'!$A:$A,$B22,'BG COMP BABF'!I:I)))/1000000)*-1 -> 80.194076 | H22: =(((-SUMIF('BG COMP BABF'!$A:$A,$B22,'BG COMP BABF'!J:J)))/1000000)*-1 -> 203.83622
B23: Clients, créditeurs | D23: Acomptes clients | F23: =(((-SUMIF('BG COMP BABF'!$A:$A,$B23,'BG COMP BABF'!H:H)))/1000000)*-1 -> 0 | G23: =(((-SUMIF('BG COMP BABF'!$A:$A,$B23,'BG COMP BABF'!I:I)))/1000000)*-1 -> 0 | H23: =(((-SUMIF('BG COMP BABF'!$A:$A,$B23,'BG COMP BABF'!J:J)))/1000000)*-1 -> 0
D24: Créances clients | F24: =SUM(F22:F23) -> 10.690842 | G24: =SUM(G22:G23) -> 80.194076 | H24: =SUM(H22:H23) -> 203.83622
B25: Fournisseurs | D25: Dettes fournisseurs | F25: =(((-SUMIF('BG COMP BABF'!$A:$A,$B25,'BG COMP BABF'!H:H)))/1000000)*-1 -> -47.847901 | G25: =(((-SUMIF('BG COMP BABF'!$A:$A,$B25,'BG COMP BABF'!I:I)))/1000000)*-1 -> -49.43267 | H25: =(((-SUMIF('BG COMP BABF'!$A:$A,$B25,'BG COMP BABF'!J:J)))/1000000)*-1 -> -60.124212
B26: Fournisseurs, débiteurs | D26: Acomptes aux fournisseurs | F26: =(((-SUMIF('BG COMP BABF'!$A:$A,$B26,'BG COMP BABF'!H:H)))/1000000)*-1 -> 0 | G26: =(((-SUMIF('BG COMP BABF'!$A:$A,$B26,'BG COMP BABF'!I:I)))/1000000)*-1 -> 0 | H26: =(((-SUMIF('BG COMP BABF'!$A:$A,$B26,'BG COMP BABF'!J:J)))/1000000)*-1 -> 1.0875
D27: Dettes fournisseurs | F27: =SUM(F25:F26) -> -47.847901 | G27: =SUM(G25:G26) -> -49.43267 | H27: =SUM(H25:H26) -> -59.036712
B28: Personnel | D28: Personnel | F28: =(((-SUMIF('BG COMP BABF'!$A:$A,$B28,'BG COMP BABF'!H:H)))/1000000)*-1 -> 3.180432 | G28: =(((-SUMIF('BG COMP BABF'!$A:$A,$B28,'BG COMP BABF'!I:I)))/1000000)*-1 -> 0.012432 | H28: =(((-SUMIF('BG COMP BABF'!$A:$A,$B28,'BG COMP BABF'!J:J)))/1000000)*-1 -> 0
B29: Charges_sociales | D29: Charges sociales | F29: =(((-SUMIF('BG COMP BABF'!$A:$A,$B29,'BG COMP BABF'!H:H)))/1000000)*-1 -> -5.36566 | G29: =(((-SUMIF('BG COMP BABF'!$A:$A,$B29,'BG COMP BABF'!I:I)))/1000000)*-1 -> -9.937768 | H29: =(((-SUMIF('BG COMP BABF'!$A:$A,$B29,'BG COMP BABF'!J:J)))/1000000)*-1 -> -15.642411
D30: Dettes et créances sociales | F30: =SUM(F28:F29) -> -2.185228 | G30: =SUM(G28:G29) -> -9.925336 | H30: =SUM(H28:H29) -> -15.642411
B31: Etat, TVA et taxes | D31: Etat, TVA et taxes | F31: =(((-SUMIF('BG COMP BABF'!$A:$A,$B31,'BG COMP BABF'!H:H)))/1000000)*-1 -> -134.01262 | G31: =(((-SUMIF('BG COMP BABF'!$A:$A,$B31,'BG COMP BABF'!I:I)))/1000000)*-1 -> -171.56861 | H31: =(((-SUMIF('BG COMP BABF'!$A:$A,$B31,'BG COMP BABF'!J:J)))/1000000)*-1 -> -240.65371
D32: Dettes et créances fiscales | F32: =F31 -> -134.01262 | G32: =G31 -> -171.56861 | H32: =H31 -> -240.65371
B33: Débiteurs et créditeurs divers | D33: Débiteurs et créditeurs divers | F33: =(((-SUMIF('BG COMP BABF'!$A:$A,$B33,'BG COMP BABF'!H:H)))/1000000)*-1 -> -78.344233 | G33: =(((-SUMIF('BG COMP BABF'!$A:$A,$B33,'BG COMP BABF'!I:I)))/1000000)*-1 -> -24.717581 | H33: =(((-SUMIF('BG COMP BABF'!$A:$A,$B33,'BG COMP BABF'!J:J)))/1000000)*-1 -> -45.558339
B34: Groupe, compte courant | D34: Groupe, compte courant | F34: =(((-SUMIF('BG COMP BABF'!$A:$A,$B34,'BG COMP BABF'!H:H)))/1000000)*-1 -> 0 | G34: =(((-SUMIF('BG COMP BABF'!$A:$A,$B34,'BG COMP BABF'!I:I)))/1000000)*-1 -> 0 | H34: =(((-SUMIF('BG COMP BABF'!$A:$A,$B34,'BG COMP BABF'!J:J)))/1000000)*-1 -> 0
B35: Dépréciations | D35: Dépréciations | F35: =(((-SUMIF('BG COMP BABF'!$A:$A,$B35,'BG COMP BABF'!H:H)))/1000000)*-1 -> 0 | G35: =(((-SUMIF('BG COMP BABF'!$A:$A,$B35,'BG COMP BABF'!I:I)))/1000000)*-1 -> 0 | H35: =(((-SUMIF('BG COMP BABF'!$A:$A,$B35,'BG COMP BABF'!J:J)))/1000000)*-1 -> 0
D36: Autres créances et dettes | F36: =SUM(F33:F35) -> -78.344233 | G36: =SUM(G33:G35) -> -24.717581 | H36: =SUM(H33:H35) -> -45.558339
D37: BFR | F37: =F36+F32+F30+F27+F24 -> -251.69914 | G37: =G36+G32+G30+G27+G24 -> -175.45012 | H37: =H36+H32+H30+H27+H24 -> -157.05496
B38: Banque | D38: Banque | F38: =(((-SUMIF('BG COMP BABF'!$A:$A,$B38,'BG COMP BABF'!H:H)))/1000000)*-1 -> 125.38724 | G38: =(((-SUMIF('BG COMP BABF'!$A:$A,$B38,'BG COMP BABF'!I:I)))/1000000)*-1 -> 164.23045 | H38: =(((-SUMIF('BG COMP BABF'!$A:$A,$B38,'BG COMP BABF'!J:J)))/1000000)*-1 -> 95.547542
B39: Crédit de trésorerie | D39: Crédit de trésorerie | F39: =(((-SUMIF('BG COMP BABF'!$A:$A,$B39,'BG COMP BABF'!H:H)))/1000000)*-1 -> 0.388579 | G39: =(((-SUMIF('BG COMP BABF'!$A:$A,$B39,'BG COMP BABF'!I:I)))/1000000)*-1 -> -53.298016 | H39: =(((-SUMIF('BG COMP BABF'!$A:$A,$B39,'BG COMP BABF'!J:J)))/1000000)*-1 -> -61.653068
B40: Caisse | D40: Caisse | F40: =(((-SUMIF('BG COMP BABF'!$A:$A,$B40,'BG COMP BABF'!H:H)))/1000000)*-1 -> 2.534162 | G40: =(((-SUMIF('BG COMP BABF'!$A:$A,$B40,'BG COMP BABF'!I:I)))/1000000)*-1 -> 1.823302 | H40: =(((-SUMIF('BG COMP BABF'!$A:$A,$B40,'BG COMP BABF'!J:J)))/1000000)*-1 -> 5.317857
B41: Virement de fonds | D41: Virement de fonds | F41: =(((-SUMIF('BG COMP BABF'!$A:$A,$B41,'BG COMP BABF'!H:H)))/1000000)*-1 -> 0 | G41: =(((-SUMIF('BG COMP BABF'!$A:$A,$B41,'BG COMP BABF'!I:I)))/1000000)*-1 -> 0 | H41: =(((-SUMIF('BG COMP BABF'!$A:$A,$B41,'BG COMP BABF'!J:J)))/1000000)*-1 -> 0
D42: Trésorerie et équivalents de trésorerie | F42: =SUM(F38:F41) -> 128.30998 | G42: =SUM(G38:G41) -> 112.75573 | H42: =SUM(H38:H41) -> 39.212331
B43: Emprunt | D43: Emprunt bancaire | F43: =(((-SUMIF('BG COMP BABF'!$A:$A,$B43,'BG COMP BABF'!H:H)))/1000000)*-1 -> 0 | G43: =(((-SUMIF('BG COMP BABF'!$A:$A,$B43,'BG COMP BABF'!I:I)))/1000000)*-1 -> 0 | H43: =(((-SUMIF('BG COMP BABF'!$A:$A,$B43,'BG COMP BABF'!J:J)))/1000000)*-1 -> 0
B44: Dette sur crédit bail | D44: Dette sur crédit bail | F44: =(((-SUMIF('BG COMP BABF'!$A:$A,$B44,'BG COMP BABF'!H:H)))/1000000)*-1 -> 0 | G44: =(((-SUMIF('BG COMP BABF'!$A:$A,$B44,'BG COMP BABF'!I:I)))/1000000)*-1 -> 0 | H44: =(((-SUMIF('BG COMP BABF'!$A:$A,$B44,'BG COMP BABF'!J:J)))/1000000)*-1 -> 0
D45: Dettes financières | F45: =SUM(F43:F44) -> 0 | G45: =SUM(G43:G44) -> 0 | H45: =SUM(H43:H44) -> 0
...

Sheet UPSLIDE_UndoFormatting
A1: 66 | B1: 25

Sheet UPSLIDE_Undo
A1: 83 | B1: 25
